2021-07-20 00:09:41,448 ERROR: Exception on /index [GET] [in /home/vitaly/python/venv/lib/python3.6/site-packages/flask/app.py:1455]
Traceback (most recent call last):
  File "/home/vitaly/python/venv/lib/python3.6/site-packages/flask/app.py", line 2070, in wsgi_app
    response = self.full_dispatch_request()
  File "/home/vitaly/python/venv/lib/python3.6/site-packages/flask/app.py", line 1515, in full_dispatch_request
    rv = self.handle_user_exception(e)
  File "/home/vitaly/python/venv/lib/python3.6/site-packages/flask/app.py", line 1513, in full_dispatch_request
    rv = self.dispatch_request()
  File "/home/vitaly/python/venv/lib/python3.6/site-packages/flask/app.py", line 1499, in dispatch_request
    return self.ensure_sync(self.view_functions[rule.endpoint])(**req.view_args)
  File "/home/vitaly/python/venv/lib/python3.6/site-packages/flask_login/utils.py", line 272, in decorated_view
    return func(*args, **kwargs)
  File "/home/vitaly/python/microblog/app/routes.py", line 30, in index
    posts=posts)
  File "/home/vitaly/python/venv/lib/python3.6/site-packages/flask/templating.py", line 150, in render_template
    ctx.app,
  File "/home/vitaly/python/venv/lib/python3.6/site-packages/flask/templating.py", line 128, in _render
    rv = template.render(context)
  File "/home/vitaly/python/venv/lib/python3.6/site-packages/jinja2/environment.py", line 1304, in render
    self.environment.handle_exception()
  File "/home/vitaly/python/venv/lib/python3.6/site-packages/jinja2/environment.py", line 925, in handle_exception
    raise rewrite_traceback_stack(source=source)
  File "/home/vitaly/python/microblog/app/templates/index.html", line 1, in top-level template code
    {% extends "base.html" %}
  File "/home/vitaly/python/microblog/app/templates/base.html", line 32, in top-level template code
    {% block content %}{% endblock %}
  File "/home/vitaly/python/microblog/app/templates/index.html", line 19, in block 'content'
    {% include '_post.html' %}
  File "/home/vitaly/python/microblog/app/templates/_post.html", line 3, in top-level template code
    <td><img src="{{ post.author.avatar(user.username) }}"></td>
  File "/home/vitaly/python/venv/lib/python3.6/site-packages/jinja2/environment.py", line 474, in getattr
    return getattr(obj, attribute)
jinja2.exceptions.UndefinedError: 'user' is undefined
2021-07-20 00:09:58,039 ERROR: Exception on /index [GET] [in /home/vitaly/python/venv/lib/python3.6/site-packages/flask/app.py:1455]
Traceback (most recent call last):
  File "/home/vitaly/python/venv/lib/python3.6/site-packages/flask/app.py", line 2070, in wsgi_app
    response = self.full_dispatch_request()
  File "/home/vitaly/python/venv/lib/python3.6/site-packages/flask/app.py", line 1515, in full_dispatch_request
    rv = self.handle_user_exception(e)
  File "/home/vitaly/python/venv/lib/python3.6/site-packages/flask/app.py", line 1513, in full_dispatch_request
    rv = self.dispatch_request()
  File "/home/vitaly/python/venv/lib/python3.6/site-packages/flask/app.py", line 1499, in dispatch_request
    return self.ensure_sync(self.view_functions[rule.endpoint])(**req.view_args)
  File "/home/vitaly/python/venv/lib/python3.6/site-packages/flask_login/utils.py", line 272, in decorated_view
    return func(*args, **kwargs)
  File "/home/vitaly/python/microblog/app/routes.py", line 30, in index
    posts=posts)
  File "/home/vitaly/python/venv/lib/python3.6/site-packages/flask/templating.py", line 150, in render_template
    ctx.app,
  File "/home/vitaly/python/venv/lib/python3.6/site-packages/flask/templating.py", line 128, in _render
    rv = template.render(context)
  File "/home/vitaly/python/venv/lib/python3.6/site-packages/jinja2/environment.py", line 1304, in render
    self.environment.handle_exception()
  File "/home/vitaly/python/venv/lib/python3.6/site-packages/jinja2/environment.py", line 925, in handle_exception
    raise rewrite_traceback_stack(source=source)
  File "/home/vitaly/python/microblog/app/templates/index.html", line 1, in top-level template code
    {% extends "base.html" %}
  File "/home/vitaly/python/microblog/app/templates/base.html", line 32, in top-level template code
    {% block content %}{% endblock %}
  File "/home/vitaly/python/microblog/app/templates/index.html", line 19, in block 'content'
    {% include '_post.html' %}
  File "/home/vitaly/python/microblog/app/templates/_post.html", line 3, in top-level template code
    <td><img src="{{ post.author.avatar(user.username) }}"></td>
  File "/home/vitaly/python/venv/lib/python3.6/site-packages/jinja2/environment.py", line 474, in getattr
    return getattr(obj, attribute)
jinja2.exceptions.UndefinedError: 'user' is undefined
2021-07-20 00:19:52,726 INFO: Microblog startup [in /home/vitaly/python/microblog/app/__init__.py:28]
2021-07-20 00:19:58,881 ERROR: Exception on /index [GET] [in /home/vitaly/python/venv/lib/python3.6/site-packages/flask/app.py:1455]
Traceback (most recent call last):
  File "/home/vitaly/python/venv/lib/python3.6/site-packages/flask/app.py", line 2070, in wsgi_app
    response = self.full_dispatch_request()
  File "/home/vitaly/python/venv/lib/python3.6/site-packages/flask/app.py", line 1515, in full_dispatch_request
    rv = self.handle_user_exception(e)
  File "/home/vitaly/python/venv/lib/python3.6/site-packages/flask/app.py", line 1513, in full_dispatch_request
    rv = self.dispatch_request()
  File "/home/vitaly/python/venv/lib/python3.6/site-packages/flask/app.py", line 1499, in dispatch_request
    return self.ensure_sync(self.view_functions[rule.endpoint])(**req.view_args)
  File "/home/vitaly/python/venv/lib/python3.6/site-packages/flask_login/utils.py", line 272, in decorated_view
    return func(*args, **kwargs)
  File "/home/vitaly/python/microblog/app/routes.py", line 38, in index
    prev_url=prev_url)
  File "/home/vitaly/python/venv/lib/python3.6/site-packages/flask/templating.py", line 148, in render_template
    ctx.app.jinja_env.get_or_select_template(template_name_or_list),
  File "/home/vitaly/python/venv/lib/python3.6/site-packages/jinja2/environment.py", line 1068, in get_or_select_template
    return self.get_template(template_name_or_list, parent, globals)
  File "/home/vitaly/python/venv/lib/python3.6/site-packages/jinja2/environment.py", line 997, in get_template
    return self._load_template(name, globals)
  File "/home/vitaly/python/venv/lib/python3.6/site-packages/jinja2/environment.py", line 958, in _load_template
    template = self.loader.load(self, name, self.make_globals(globals))
  File "/home/vitaly/python/venv/lib/python3.6/site-packages/jinja2/loaders.py", line 137, in load
    code = environment.compile(source, name, filename)
  File "/home/vitaly/python/venv/lib/python3.6/site-packages/jinja2/environment.py", line 757, in compile
    self.handle_exception(source=source_hint)
  File "/home/vitaly/python/venv/lib/python3.6/site-packages/jinja2/environment.py", line 925, in handle_exception
    raise rewrite_traceback_stack(source=source)
  File "/home/vitaly/python/microblog/app/templates/index.html", line 1, in template
    {{% extends "base.html" %}
jinja2.exceptions.TemplateSyntaxError: unexpected '%'
2021-07-20 00:21:45,810 INFO: Microblog startup [in /home/vitaly/python/microblog/app/__init__.py:28]
2021-07-20 00:21:50,660 ERROR: Exception on /index [GET] [in /home/vitaly/python/venv/lib/python3.6/site-packages/flask/app.py:1455]
Traceback (most recent call last):
  File "/home/vitaly/python/venv/lib/python3.6/site-packages/flask/app.py", line 2070, in wsgi_app
    response = self.full_dispatch_request()
  File "/home/vitaly/python/venv/lib/python3.6/site-packages/flask/app.py", line 1515, in full_dispatch_request
    rv = self.handle_user_exception(e)
  File "/home/vitaly/python/venv/lib/python3.6/site-packages/flask/app.py", line 1513, in full_dispatch_request
    rv = self.dispatch_request()
  File "/home/vitaly/python/venv/lib/python3.6/site-packages/flask/app.py", line 1499, in dispatch_request
    return self.ensure_sync(self.view_functions[rule.endpoint])(**req.view_args)
  File "/home/vitaly/python/venv/lib/python3.6/site-packages/flask_login/utils.py", line 272, in decorated_view
    return func(*args, **kwargs)
  File "/home/vitaly/python/microblog/app/routes.py", line 38, in index
    prev_url=prev_url)
  File "/home/vitaly/python/venv/lib/python3.6/site-packages/flask/templating.py", line 150, in render_template
    ctx.app,
  File "/home/vitaly/python/venv/lib/python3.6/site-packages/flask/templating.py", line 128, in _render
    rv = template.render(context)
  File "/home/vitaly/python/venv/lib/python3.6/site-packages/jinja2/environment.py", line 1304, in render
    self.environment.handle_exception()
  File "/home/vitaly/python/venv/lib/python3.6/site-packages/jinja2/environment.py", line 925, in handle_exception
    raise rewrite_traceback_stack(source=source)
  File "/home/vitaly/python/microblog/app/templates/index.html", line 1, in top-level template code
    {% extends "base.html" %}
  File "/home/vitaly/python/microblog/app/templates/base.html", line 32, in top-level template code
    {% block content %}{% endblock %}
  File "/home/vitaly/python/microblog/app/templates/index.html", line 19, in block 'content'
    {% include '_post.html' %}
  File "/home/vitaly/python/microblog/app/templates/_post.html", line 3, in top-level template code
    <td><img src="{{ post.author.avatar(user.username) }}"></td>
  File "/home/vitaly/python/venv/lib/python3.6/site-packages/jinja2/environment.py", line 474, in getattr
    return getattr(obj, attribute)
jinja2.exceptions.UndefinedError: 'user' is undefined
