2021-07-20 23:24:29,871 ERROR: Exception on /login [GET] [in /home/vitaly/python/venv/lib/python3.6/site-packages/flask/app.py:1455]
Traceback (most recent call last):
  File "/home/vitaly/python/venv/lib/python3.6/site-packages/flask/app.py", line 2070, in wsgi_app
    response = self.full_dispatch_request()
  File "/home/vitaly/python/venv/lib/python3.6/site-packages/flask/app.py", line 1515, in full_dispatch_request
    rv = self.handle_user_exception(e)
  File "/home/vitaly/python/venv/lib/python3.6/site-packages/flask/app.py", line 1513, in full_dispatch_request
    rv = self.dispatch_request()
  File "/home/vitaly/python/venv/lib/python3.6/site-packages/flask/app.py", line 1499, in dispatch_request
    return self.ensure_sync(self.view_functions[rule.endpoint])(**req.view_args)
  File "/home/vitaly/python/microblog/app/routes.py", line 70, in login
    return render_template('login.html', title='Sign In', form=form)
  File "/home/vitaly/python/venv/lib/python3.6/site-packages/flask/templating.py", line 150, in render_template
    ctx.app,
  File "/home/vitaly/python/venv/lib/python3.6/site-packages/flask/templating.py", line 128, in _render
    rv = template.render(context)
  File "/home/vitaly/python/venv/lib/python3.6/site-packages/jinja2/environment.py", line 1304, in render
    self.environment.handle_exception()
  File "/home/vitaly/python/venv/lib/python3.6/site-packages/jinja2/environment.py", line 925, in handle_exception
    raise rewrite_traceback_stack(source=source)
  File "/home/vitaly/python/microblog/app/templates/login.html", line 2, in top-level template code
    {% import 'bootstrap/wtf.html' as wtf %}
  File "/home/vitaly/python/microblog/app/templates/base.html", line 1, in top-level template code
    {% extends 'bootstrap/base.html' %}
  File "/home/vitaly/python/venv/lib/python3.6/site-packages/flask_bootstrap/templates/bootstrap/base.html", line 1, in top-level template code
    {% block doc -%}
  File "/home/vitaly/python/venv/lib/python3.6/site-packages/flask_bootstrap/templates/bootstrap/base.html", line 4, in block 'doc'
    {%- block html %}
  File "/home/vitaly/python/venv/lib/python3.6/site-packages/flask_bootstrap/templates/bootstrap/base.html", line 20, in block 'html'
    {% block body -%}
  File "/home/vitaly/python/venv/lib/python3.6/site-packages/flask_bootstrap/templates/bootstrap/base.html", line 23, in block 'body'
    {% block content -%}
  File "/home/vitaly/python/microblog/app/templates/base.html", line 48, in block 'content'
    {% block app_content %}{% endblock %}
  File "/home/vitaly/python/microblog/app/templates/login.html", line 15, in block 'app_content'
    <a href="{{ url_for('reset_password_request') }}">Click to Reset It</a>
  File "/home/vitaly/python/venv/lib/python3.6/site-packages/flask/helpers.py", line 338, in url_for
    return appctx.app.handle_url_build_error(error, endpoint, values)
  File "/home/vitaly/python/venv/lib/python3.6/site-packages/flask/helpers.py", line 326, in url_for
    endpoint, values, method=method, force_external=external
  File "/home/vitaly/python/venv/lib/python3.6/site-packages/werkzeug/routing.py", line 2305, in build
    raise BuildError(endpoint, values, method, self)
werkzeug.routing.BuildError: Could not build url for endpoint 'reset_password_request'. Did you mean 'edit_profile' instead?
2021-07-20 23:25:36,138 ERROR: Exception on /login [GET] [in /home/vitaly/python/venv/lib/python3.6/site-packages/flask/app.py:1455]
Traceback (most recent call last):
  File "/home/vitaly/python/venv/lib/python3.6/site-packages/flask/app.py", line 2070, in wsgi_app
    response = self.full_dispatch_request()
  File "/home/vitaly/python/venv/lib/python3.6/site-packages/flask/app.py", line 1515, in full_dispatch_request
    rv = self.handle_user_exception(e)
  File "/home/vitaly/python/venv/lib/python3.6/site-packages/flask/app.py", line 1513, in full_dispatch_request
    rv = self.dispatch_request()
  File "/home/vitaly/python/venv/lib/python3.6/site-packages/flask/app.py", line 1499, in dispatch_request
    return self.ensure_sync(self.view_functions[rule.endpoint])(**req.view_args)
  File "/home/vitaly/python/microblog/app/routes.py", line 70, in login
    return render_template('login.html', title='Sign In', form=form)
  File "/home/vitaly/python/venv/lib/python3.6/site-packages/flask/templating.py", line 150, in render_template
    ctx.app,
  File "/home/vitaly/python/venv/lib/python3.6/site-packages/flask/templating.py", line 128, in _render
    rv = template.render(context)
  File "/home/vitaly/python/venv/lib/python3.6/site-packages/jinja2/environment.py", line 1304, in render
    self.environment.handle_exception()
  File "/home/vitaly/python/venv/lib/python3.6/site-packages/jinja2/environment.py", line 925, in handle_exception
    raise rewrite_traceback_stack(source=source)
  File "/home/vitaly/python/microblog/app/templates/login.html", line 2, in top-level template code
    {% import 'bootstrap/wtf.html' as wtf %}
  File "/home/vitaly/python/microblog/app/templates/base.html", line 1, in top-level template code
    {% extends 'bootstrap/base.html' %}
  File "/home/vitaly/python/venv/lib/python3.6/site-packages/flask_bootstrap/templates/bootstrap/base.html", line 1, in top-level template code
    {% block doc -%}
  File "/home/vitaly/python/venv/lib/python3.6/site-packages/flask_bootstrap/templates/bootstrap/base.html", line 4, in block 'doc'
    {%- block html %}
  File "/home/vitaly/python/venv/lib/python3.6/site-packages/flask_bootstrap/templates/bootstrap/base.html", line 20, in block 'html'
    {% block body -%}
  File "/home/vitaly/python/venv/lib/python3.6/site-packages/flask_bootstrap/templates/bootstrap/base.html", line 23, in block 'body'
    {% block content -%}
  File "/home/vitaly/python/microblog/app/templates/base.html", line 48, in block 'content'
    {% block app_content %}{% endblock %}
  File "/home/vitaly/python/microblog/app/templates/login.html", line 15, in block 'app_content'
    <a href="{{ url_for('reset_password_request') }}">Click to Reset It</a>
  File "/home/vitaly/python/venv/lib/python3.6/site-packages/flask/helpers.py", line 338, in url_for
    return appctx.app.handle_url_build_error(error, endpoint, values)
  File "/home/vitaly/python/venv/lib/python3.6/site-packages/flask/helpers.py", line 326, in url_for
    endpoint, values, method=method, force_external=external
  File "/home/vitaly/python/venv/lib/python3.6/site-packages/werkzeug/routing.py", line 2305, in build
    raise BuildError(endpoint, values, method, self)
werkzeug.routing.BuildError: Could not build url for endpoint 'reset_password_request'. Did you mean 'edit_profile' instead?
2021-07-20 23:25:44,343 ERROR: Exception on /login [GET] [in /home/vitaly/python/venv/lib/python3.6/site-packages/flask/app.py:1455]
Traceback (most recent call last):
  File "/home/vitaly/python/venv/lib/python3.6/site-packages/flask/app.py", line 2070, in wsgi_app
    response = self.full_dispatch_request()
  File "/home/vitaly/python/venv/lib/python3.6/site-packages/flask/app.py", line 1515, in full_dispatch_request
    rv = self.handle_user_exception(e)
  File "/home/vitaly/python/venv/lib/python3.6/site-packages/flask/app.py", line 1513, in full_dispatch_request
    rv = self.dispatch_request()
  File "/home/vitaly/python/venv/lib/python3.6/site-packages/flask/app.py", line 1499, in dispatch_request
    return self.ensure_sync(self.view_functions[rule.endpoint])(**req.view_args)
  File "/home/vitaly/python/microblog/app/routes.py", line 70, in login
    return render_template('login.html', title='Sign In', form=form)
  File "/home/vitaly/python/venv/lib/python3.6/site-packages/flask/templating.py", line 150, in render_template
    ctx.app,
  File "/home/vitaly/python/venv/lib/python3.6/site-packages/flask/templating.py", line 128, in _render
    rv = template.render(context)
  File "/home/vitaly/python/venv/lib/python3.6/site-packages/jinja2/environment.py", line 1304, in render
    self.environment.handle_exception()
  File "/home/vitaly/python/venv/lib/python3.6/site-packages/jinja2/environment.py", line 925, in handle_exception
    raise rewrite_traceback_stack(source=source)
  File "/home/vitaly/python/microblog/app/templates/login.html", line 2, in top-level template code
    {% import 'bootstrap/wtf.html' as wtf %}
  File "/home/vitaly/python/microblog/app/templates/base.html", line 1, in top-level template code
    {% extends 'bootstrap/base.html' %}
  File "/home/vitaly/python/venv/lib/python3.6/site-packages/flask_bootstrap/templates/bootstrap/base.html", line 1, in top-level template code
    {% block doc -%}
  File "/home/vitaly/python/venv/lib/python3.6/site-packages/flask_bootstrap/templates/bootstrap/base.html", line 4, in block 'doc'
    {%- block html %}
  File "/home/vitaly/python/venv/lib/python3.6/site-packages/flask_bootstrap/templates/bootstrap/base.html", line 20, in block 'html'
    {% block body -%}
  File "/home/vitaly/python/venv/lib/python3.6/site-packages/flask_bootstrap/templates/bootstrap/base.html", line 23, in block 'body'
    {% block content -%}
  File "/home/vitaly/python/microblog/app/templates/base.html", line 48, in block 'content'
    {% block app_content %}{% endblock %}
  File "/home/vitaly/python/microblog/app/templates/login.html", line 15, in block 'app_content'
    <a href="{{ url_for('reset_password_request') }}">Click to Reset It</a>
  File "/home/vitaly/python/venv/lib/python3.6/site-packages/flask/helpers.py", line 338, in url_for
    return appctx.app.handle_url_build_error(error, endpoint, values)
  File "/home/vitaly/python/venv/lib/python3.6/site-packages/flask/helpers.py", line 326, in url_for
    endpoint, values, method=method, force_external=external
  File "/home/vitaly/python/venv/lib/python3.6/site-packages/werkzeug/routing.py", line 2305, in build
    raise BuildError(endpoint, values, method, self)
werkzeug.routing.BuildError: Could not build url for endpoint 'reset_password_request'. Did you mean 'edit_profile' instead?
